2024-04-29 10:02:44,722 - config - ERROR - Статус код: 400
2024-04-29 10:07:46,289 - TeleBot - ERROR - Infinity polling: polling exited
2024-04-29 10:07:46,290 - TeleBot - ERROR - Break infinity polling
2024-04-29 10:14:04,017 - TeleBot - ERROR - Infinity polling: polling exited
2024-04-29 10:14:04,017 - TeleBot - ERROR - Break infinity polling
2024-04-29 10:14:32,022 - TeleBot - ERROR - Infinity polling exception: TeleBot.register_next_step_handler() missing 1 required positional argument: 'callback'
2024-04-29 10:14:32,023 - TeleBot - ERROR - Exception traceback:
Traceback (most recent call last):
  File "C:\Users\PC\Desktop\pythonProject\Project11\.venv\Lib\site-packages\telebot\__init__.py", line 1081, in infinity_polling
    self.polling(non_stop=True, timeout=timeout, long_polling_timeout=long_polling_timeout,
  File "C:\Users\PC\Desktop\pythonProject\Project11\.venv\Lib\site-packages\telebot\__init__.py", line 1169, in polling
    self.__threaded_polling(non_stop=non_stop, interval=interval, timeout=timeout, long_polling_timeout=long_polling_timeout,
  File "C:\Users\PC\Desktop\pythonProject\Project11\.venv\Lib\site-packages\telebot\__init__.py", line 1244, in __threaded_polling
    raise e
  File "C:\Users\PC\Desktop\pythonProject\Project11\.venv\Lib\site-packages\telebot\__init__.py", line 1206, in __threaded_polling
    self.worker_pool.raise_exceptions()
  File "C:\Users\PC\Desktop\pythonProject\Project11\.venv\Lib\site-packages\telebot\util.py", line 150, in raise_exceptions
    raise self.exception_info
  File "C:\Users\PC\Desktop\pythonProject\Project11\.venv\Lib\site-packages\telebot\util.py", line 93, in run
    task(*args, **kwargs)
  File "C:\Users\PC\Desktop\pythonProject\Project11\.venv\Lib\site-packages\telebot\__init__.py", line 8404, in _run_middlewares_and_handler
    result = handler['function'](message)
             ^^^^^^^^^^^^^^^^^^^^^^^^^^^^
  File "C:\Users\PC\Desktop\pythonProject\Project11\bot.py", line 14, in for_text
    bot.register_next_step_handler(message, )
TypeError: TeleBot.register_next_step_handler() missing 1 required positional argument: 'callback'

2024-04-29 10:16:06,451 - TeleBot - ERROR - Infinity polling: polling exited
2024-04-29 10:16:06,451 - TeleBot - ERROR - Break infinity polling
2024-04-29 17:40:14,431 - TeleBot - ERROR - Infinity polling exception: TeleBot.register_next_step_handler() missing 1 required positional argument: 'callback'
2024-04-29 17:40:14,432 - TeleBot - ERROR - Exception traceback:
Traceback (most recent call last):
  File "C:\Users\PC\Desktop\pythonProject\Project11\.venv\Lib\site-packages\telebot\__init__.py", line 1081, in infinity_polling
    self.polling(non_stop=True, timeout=timeout, long_polling_timeout=long_polling_timeout,
  File "C:\Users\PC\Desktop\pythonProject\Project11\.venv\Lib\site-packages\telebot\__init__.py", line 1169, in polling
    self.__threaded_polling(non_stop=non_stop, interval=interval, timeout=timeout, long_polling_timeout=long_polling_timeout,
  File "C:\Users\PC\Desktop\pythonProject\Project11\.venv\Lib\site-packages\telebot\__init__.py", line 1244, in __threaded_polling
    raise e
  File "C:\Users\PC\Desktop\pythonProject\Project11\.venv\Lib\site-packages\telebot\__init__.py", line 1206, in __threaded_polling
    self.worker_pool.raise_exceptions()
  File "C:\Users\PC\Desktop\pythonProject\Project11\.venv\Lib\site-packages\telebot\util.py", line 150, in raise_exceptions
    raise self.exception_info
  File "C:\Users\PC\Desktop\pythonProject\Project11\.venv\Lib\site-packages\telebot\util.py", line 93, in run
    task(*args, **kwargs)
  File "C:\Users\PC\Desktop\pythonProject\Project11\.venv\Lib\site-packages\telebot\__init__.py", line 8404, in _run_middlewares_and_handler
    result = handler['function'](message)
             ^^^^^^^^^^^^^^^^^^^^^^^^^^^^
  File "C:\Users\PC\Desktop\pythonProject\Project11\bot.py", line 15, in for_text
    bot.register_next_step_handler(message, )
TypeError: TeleBot.register_next_step_handler() missing 1 required positional argument: 'callback'

2024-04-29 17:40:29,469 - TeleBot - ERROR - Infinity polling: polling exited
2024-04-29 17:40:29,469 - TeleBot - ERROR - Break infinity polling
2024-04-29 17:41:03,024 - TeleBot - ERROR - Infinity polling exception: TeleBot.register_next_step_handler() missing 1 required positional argument: 'callback'
2024-04-29 17:41:03,024 - TeleBot - ERROR - Exception traceback:
Traceback (most recent call last):
  File "C:\Users\PC\Desktop\pythonProject\Project11\.venv\Lib\site-packages\telebot\__init__.py", line 1081, in infinity_polling
    self.polling(non_stop=True, timeout=timeout, long_polling_timeout=long_polling_timeout,
  File "C:\Users\PC\Desktop\pythonProject\Project11\.venv\Lib\site-packages\telebot\__init__.py", line 1169, in polling
    self.__threaded_polling(non_stop=non_stop, interval=interval, timeout=timeout, long_polling_timeout=long_polling_timeout,
  File "C:\Users\PC\Desktop\pythonProject\Project11\.venv\Lib\site-packages\telebot\__init__.py", line 1244, in __threaded_polling
    raise e
  File "C:\Users\PC\Desktop\pythonProject\Project11\.venv\Lib\site-packages\telebot\__init__.py", line 1206, in __threaded_polling
    self.worker_pool.raise_exceptions()
  File "C:\Users\PC\Desktop\pythonProject\Project11\.venv\Lib\site-packages\telebot\util.py", line 150, in raise_exceptions
    raise self.exception_info
  File "C:\Users\PC\Desktop\pythonProject\Project11\.venv\Lib\site-packages\telebot\util.py", line 93, in run
    task(*args, **kwargs)
  File "C:\Users\PC\Desktop\pythonProject\Project11\.venv\Lib\site-packages\telebot\__init__.py", line 8404, in _run_middlewares_and_handler
    result = handler['function'](message)
             ^^^^^^^^^^^^^^^^^^^^^^^^^^^^
  File "C:\Users\PC\Desktop\pythonProject\Project11\bot.py", line 15, in for_text
    bot.register_next_step_handler(message, )
TypeError: TeleBot.register_next_step_handler() missing 1 required positional argument: 'callback'

2024-04-29 17:45:51,386 - TeleBot - ERROR - Infinity polling: polling exited
2024-04-29 17:45:51,386 - TeleBot - ERROR - Break infinity polling
2024-04-29 17:46:02,077 - TeleBot - ERROR - Infinity polling exception: TeleBot.register_next_step_handler() missing 1 required positional argument: 'callback'
2024-04-29 17:46:02,078 - TeleBot - ERROR - Exception traceback:
Traceback (most recent call last):
  File "C:\Users\PC\Desktop\pythonProject\Project11\.venv\Lib\site-packages\telebot\__init__.py", line 1081, in infinity_polling
    self.polling(non_stop=True, timeout=timeout, long_polling_timeout=long_polling_timeout,
  File "C:\Users\PC\Desktop\pythonProject\Project11\.venv\Lib\site-packages\telebot\__init__.py", line 1169, in polling
    self.__threaded_polling(non_stop=non_stop, interval=interval, timeout=timeout, long_polling_timeout=long_polling_timeout,
  File "C:\Users\PC\Desktop\pythonProject\Project11\.venv\Lib\site-packages\telebot\__init__.py", line 1244, in __threaded_polling
    raise e
  File "C:\Users\PC\Desktop\pythonProject\Project11\.venv\Lib\site-packages\telebot\__init__.py", line 1206, in __threaded_polling
    self.worker_pool.raise_exceptions()
  File "C:\Users\PC\Desktop\pythonProject\Project11\.venv\Lib\site-packages\telebot\util.py", line 150, in raise_exceptions
    raise self.exception_info
  File "C:\Users\PC\Desktop\pythonProject\Project11\.venv\Lib\site-packages\telebot\util.py", line 93, in run
    task(*args, **kwargs)
  File "C:\Users\PC\Desktop\pythonProject\Project11\.venv\Lib\site-packages\telebot\__init__.py", line 8404, in _run_middlewares_and_handler
    result = handler['function'](message)
             ^^^^^^^^^^^^^^^^^^^^^^^^^^^^
  File "C:\Users\PC\Desktop\pythonProject\Project11\bot.py", line 15, in for_text
    bot.register_next_step_handler(message, )
TypeError: TeleBot.register_next_step_handler() missing 1 required positional argument: 'callback'

2024-04-29 17:46:31,877 - TeleBot - ERROR - Infinity polling: polling exited
2024-04-29 17:46:31,877 - TeleBot - ERROR - Break infinity polling
2024-04-29 17:51:06,300 - config - ERROR - Не существующий пользователь.
2024-04-29 17:51:12,734 - TeleBot - ERROR - Infinity polling: polling exited
2024-04-29 17:51:12,734 - TeleBot - ERROR - Break infinity polling
2024-04-29 17:51:13,662 - config - ERROR - Не существующий пользователь.
2024-04-29 17:51:57,591 - config - ERROR - Не существующий пользователь.
2024-04-29 17:52:03,999 - TeleBot - ERROR - Infinity polling: polling exited
2024-04-29 17:52:03,999 - TeleBot - ERROR - Break infinity polling
2024-04-29 17:52:07,557 - config - ERROR - Не существующий пользователь.
2024-04-29 17:52:41,534 - TeleBot - ERROR - Infinity polling: polling exited
2024-04-29 17:52:41,534 - TeleBot - ERROR - Break infinity polling
2024-04-29 17:52:42,655 - config - ERROR - Не существующий пользователь.
2024-04-29 17:54:13,580 - TeleBot - ERROR - Infinity polling: polling exited
2024-04-29 17:54:13,580 - TeleBot - ERROR - Break infinity polling
2024-04-29 17:55:43,102 - config - ERROR - Не существующий пользователь.
2024-05-01 10:05:47,114 - config - ERROR - Не существующий пользователь.
2024-05-01 14:00:40,116 - TeleBot - ERROR - Infinity polling exception: ('Connection aborted.', RemoteDisconnected('Remote end closed connection without response'))
2024-05-01 14:00:40,118 - TeleBot - ERROR - Exception traceback:
Traceback (most recent call last):
  File "C:\Users\PC\Desktop\pythonProject\Project11\.venv\Lib\site-packages\urllib3\connectionpool.py", line 793, in urlopen
    response = self._make_request(
               ^^^^^^^^^^^^^^^^^^^
  File "C:\Users\PC\Desktop\pythonProject\Project11\.venv\Lib\site-packages\urllib3\connectionpool.py", line 537, in _make_request
    response = conn.getresponse()
               ^^^^^^^^^^^^^^^^^^
  File "C:\Users\PC\Desktop\pythonProject\Project11\.venv\Lib\site-packages\urllib3\connection.py", line 466, in getresponse
    httplib_response = super().getresponse()
                       ^^^^^^^^^^^^^^^^^^^^^
  File "C:\Users\PC\AppData\Local\Programs\Python\Python312\Lib\http\client.py", line 1423, in getresponse
    response.begin()
  File "C:\Users\PC\AppData\Local\Programs\Python\Python312\Lib\http\client.py", line 331, in begin
    version, status, reason = self._read_status()
                              ^^^^^^^^^^^^^^^^^^^
  File "C:\Users\PC\AppData\Local\Programs\Python\Python312\Lib\http\client.py", line 300, in _read_status
    raise RemoteDisconnected("Remote end closed connection without"
http.client.RemoteDisconnected: Remote end closed connection without response

During handling of the above exception, another exception occurred:

Traceback (most recent call last):
  File "C:\Users\PC\Desktop\pythonProject\Project11\.venv\Lib\site-packages\requests\adapters.py", line 486, in send
    resp = conn.urlopen(
           ^^^^^^^^^^^^^
  File "C:\Users\PC\Desktop\pythonProject\Project11\.venv\Lib\site-packages\urllib3\connectionpool.py", line 847, in urlopen
    retries = retries.increment(
              ^^^^^^^^^^^^^^^^^^
  File "C:\Users\PC\Desktop\pythonProject\Project11\.venv\Lib\site-packages\urllib3\util\retry.py", line 470, in increment
    raise reraise(type(error), error, _stacktrace)
          ^^^^^^^^^^^^^^^^^^^^^^^^^^^^^^^^^^^^^^^^
  File "C:\Users\PC\Desktop\pythonProject\Project11\.venv\Lib\site-packages\urllib3\util\util.py", line 38, in reraise
    raise value.with_traceback(tb)
  File "C:\Users\PC\Desktop\pythonProject\Project11\.venv\Lib\site-packages\urllib3\connectionpool.py", line 793, in urlopen
    response = self._make_request(
               ^^^^^^^^^^^^^^^^^^^
  File "C:\Users\PC\Desktop\pythonProject\Project11\.venv\Lib\site-packages\urllib3\connectionpool.py", line 537, in _make_request
    response = conn.getresponse()
               ^^^^^^^^^^^^^^^^^^
  File "C:\Users\PC\Desktop\pythonProject\Project11\.venv\Lib\site-packages\urllib3\connection.py", line 466, in getresponse
    httplib_response = super().getresponse()
                       ^^^^^^^^^^^^^^^^^^^^^
  File "C:\Users\PC\AppData\Local\Programs\Python\Python312\Lib\http\client.py", line 1423, in getresponse
    response.begin()
  File "C:\Users\PC\AppData\Local\Programs\Python\Python312\Lib\http\client.py", line 331, in begin
    version, status, reason = self._read_status()
                              ^^^^^^^^^^^^^^^^^^^
  File "C:\Users\PC\AppData\Local\Programs\Python\Python312\Lib\http\client.py", line 300, in _read_status
    raise RemoteDisconnected("Remote end closed connection without"
urllib3.exceptions.ProtocolError: ('Connection aborted.', RemoteDisconnected('Remote end closed connection without response'))

During handling of the above exception, another exception occurred:

Traceback (most recent call last):
  File "C:\Users\PC\Desktop\pythonProject\Project11\.venv\Lib\site-packages\telebot\__init__.py", line 1081, in infinity_polling
    self.polling(non_stop=True, timeout=timeout, long_polling_timeout=long_polling_timeout,
  File "C:\Users\PC\Desktop\pythonProject\Project11\.venv\Lib\site-packages\telebot\__init__.py", line 1169, in polling
    self.__threaded_polling(non_stop=non_stop, interval=interval, timeout=timeout, long_polling_timeout=long_polling_timeout,
  File "C:\Users\PC\Desktop\pythonProject\Project11\.venv\Lib\site-packages\telebot\__init__.py", line 1244, in __threaded_polling
    raise e
  File "C:\Users\PC\Desktop\pythonProject\Project11\.venv\Lib\site-packages\telebot\__init__.py", line 1205, in __threaded_polling
    polling_thread.raise_exceptions()
  File "C:\Users\PC\Desktop\pythonProject\Project11\.venv\Lib\site-packages\telebot\util.py", line 111, in raise_exceptions
    raise self.exception_info
  File "C:\Users\PC\Desktop\pythonProject\Project11\.venv\Lib\site-packages\telebot\util.py", line 93, in run
    task(*args, **kwargs)
  File "C:\Users\PC\Desktop\pythonProject\Project11\.venv\Lib\site-packages\telebot\__init__.py", line 675, in __retrieve_updates
    updates = self.get_updates(offset=(self.last_update_id + 1),
             ^^^^^^^^^^^^^^^^^^^^^^^^^^^^^^^^^^^^^^^^^^^^^^^^^^
  File "C:\Users\PC\Desktop\pythonProject\Project11\.venv\Lib\site-packages\telebot\__init__.py", line 647, in get_updates
    json_updates = apihelper.get_updates(
                   ^^^^^^^^^^^^^^^^^^^^^^
  File "C:\Users\PC\Desktop\pythonProject\Project11\.venv\Lib\site-packages\telebot\apihelper.py", line 327, in get_updates
    return _make_request(token, method_url, params=payload)
           ^^^^^^^^^^^^^^^^^^^^^^^^^^^^^^^^^^^^^^^^^^^^^^^^
  File "C:\Users\PC\Desktop\pythonProject\Project11\.venv\Lib\site-packages\telebot\apihelper.py", line 161, in _make_request
    result = _get_req_session().request(
             ^^^^^^^^^^^^^^^^^^^^^^^^^^^
  File "C:\Users\PC\Desktop\pythonProject\Project11\.venv\Lib\site-packages\requests\sessions.py", line 589, in request
    resp = self.send(prep, **send_kwargs)
           ^^^^^^^^^^^^^^^^^^^^^^^^^^^^^^
  File "C:\Users\PC\Desktop\pythonProject\Project11\.venv\Lib\site-packages\requests\sessions.py", line 703, in send
    r = adapter.send(request, **kwargs)
        ^^^^^^^^^^^^^^^^^^^^^^^^^^^^^^^
  File "C:\Users\PC\Desktop\pythonProject\Project11\.venv\Lib\site-packages\requests\adapters.py", line 501, in send
    raise ConnectionError(err, request=request)
requests.exceptions.ConnectionError: ('Connection aborted.', RemoteDisconnected('Remote end closed connection without response'))

2024-05-01 14:00:43,275 - TeleBot - ERROR - Infinity polling exception: HTTPSConnectionPool(host='api.telegram.org', port=443): Max retries exceeded with url: /bot6808640258:AAGUcVSRqPciK6qeM30saCt-6jquSDP4gWI/getUpdates?offset=56924450&timeout=20 (Caused by NameResolutionError("<urllib3.connection.HTTPSConnection object at 0x000001ABEB3B0C50>: Failed to resolve 'api.telegram.org' ([Errno 11001] getaddrinfo failed)"))
2024-05-01 14:00:43,277 - TeleBot - ERROR - Exception traceback:
Traceback (most recent call last):
  File "C:\Users\PC\Desktop\pythonProject\Project11\.venv\Lib\site-packages\urllib3\connection.py", line 198, in _new_conn
    sock = connection.create_connection(
           ^^^^^^^^^^^^^^^^^^^^^^^^^^^^^
  File "C:\Users\PC\Desktop\pythonProject\Project11\.venv\Lib\site-packages\urllib3\util\connection.py", line 60, in create_connection
    for res in socket.getaddrinfo(host, port, family, socket.SOCK_STREAM):
               ^^^^^^^^^^^^^^^^^^^^^^^^^^^^^^^^^^^^^^^^^^^^^^^^^^^^^^^^^^
  File "C:\Users\PC\AppData\Local\Programs\Python\Python312\Lib\socket.py", line 963, in getaddrinfo
    for res in _socket.getaddrinfo(host, port, family, type, proto, flags):
               ^^^^^^^^^^^^^^^^^^^^^^^^^^^^^^^^^^^^^^^^^^^^^^^^^^^^^^^^^^^
socket.gaierror: [Errno 11001] getaddrinfo failed

The above exception was the direct cause of the following exception:

Traceback (most recent call last):
  File "C:\Users\PC\Desktop\pythonProject\Project11\.venv\Lib\site-packages\urllib3\connectionpool.py", line 793, in urlopen
    response = self._make_request(
               ^^^^^^^^^^^^^^^^^^^
  File "C:\Users\PC\Desktop\pythonProject\Project11\.venv\Lib\site-packages\urllib3\connectionpool.py", line 491, in _make_request
    raise new_e
  File "C:\Users\PC\Desktop\pythonProject\Project11\.venv\Lib\site-packages\urllib3\connectionpool.py", line 467, in _make_request
    self._validate_conn(conn)
  File "C:\Users\PC\Desktop\pythonProject\Project11\.venv\Lib\site-packages\urllib3\connectionpool.py", line 1099, in _validate_conn
    conn.connect()
  File "C:\Users\PC\Desktop\pythonProject\Project11\.venv\Lib\site-packages\urllib3\connection.py", line 616, in connect
    self.sock = sock = self._new_conn()
                       ^^^^^^^^^^^^^^^^
  File "C:\Users\PC\Desktop\pythonProject\Project11\.venv\Lib\site-packages\urllib3\connection.py", line 205, in _new_conn
    raise NameResolutionError(self.host, self, e) from e
urllib3.exceptions.NameResolutionError: <urllib3.connection.HTTPSConnection object at 0x000001ABEB3B0C50>: Failed to resolve 'api.telegram.org' ([Errno 11001] getaddrinfo failed)

The above exception was the direct cause of the following exception:

Traceback (most recent call last):
  File "C:\Users\PC\Desktop\pythonProject\Project11\.venv\Lib\site-packages\requests\adapters.py", line 486, in send
    resp = conn.urlopen(
           ^^^^^^^^^^^^^
  File "C:\Users\PC\Desktop\pythonProject\Project11\.venv\Lib\site-packages\urllib3\connectionpool.py", line 847, in urlopen
    retries = retries.increment(
              ^^^^^^^^^^^^^^^^^^
  File "C:\Users\PC\Desktop\pythonProject\Project11\.venv\Lib\site-packages\urllib3\util\retry.py", line 515, in increment
    raise MaxRetryError(_pool, url, reason) from reason  # type: ignore[arg-type]
    ^^^^^^^^^^^^^^^^^^^^^^^^^^^^^^^^^^^^^^^^^^^^^^^^^^^
urllib3.exceptions.MaxRetryError: HTTPSConnectionPool(host='api.telegram.org', port=443): Max retries exceeded with url: /bot6808640258:AAGUcVSRqPciK6qeM30saCt-6jquSDP4gWI/getUpdates?offset=56924450&timeout=20 (Caused by NameResolutionError("<urllib3.connection.HTTPSConnection object at 0x000001ABEB3B0C50>: Failed to resolve 'api.telegram.org' ([Errno 11001] getaddrinfo failed)"))

During handling of the above exception, another exception occurred:

Traceback (most recent call last):
  File "C:\Users\PC\Desktop\pythonProject\Project11\.venv\Lib\site-packages\telebot\__init__.py", line 1081, in infinity_polling
    self.polling(non_stop=True, timeout=timeout, long_polling_timeout=long_polling_timeout,
  File "C:\Users\PC\Desktop\pythonProject\Project11\.venv\Lib\site-packages\telebot\__init__.py", line 1169, in polling
    self.__threaded_polling(non_stop=non_stop, interval=interval, timeout=timeout, long_polling_timeout=long_polling_timeout,
  File "C:\Users\PC\Desktop\pythonProject\Project11\.venv\Lib\site-packages\telebot\__init__.py", line 1244, in __threaded_polling
    raise e
  File "C:\Users\PC\Desktop\pythonProject\Project11\.venv\Lib\site-packages\telebot\__init__.py", line 1205, in __threaded_polling
    polling_thread.raise_exceptions()
  File "C:\Users\PC\Desktop\pythonProject\Project11\.venv\Lib\site-packages\telebot\util.py", line 111, in raise_exceptions
    raise self.exception_info
  File "C:\Users\PC\Desktop\pythonProject\Project11\.venv\Lib\site-packages\telebot\util.py", line 93, in run
    task(*args, **kwargs)
  File "C:\Users\PC\Desktop\pythonProject\Project11\.venv\Lib\site-packages\telebot\__init__.py", line 675, in __retrieve_updates
    updates = self.get_updates(offset=(self.last_update_id + 1),
             ^^^^^^^^^^^^^^^^^^^^^^^^^^^^^^^^^^^^^^^^^^^^^^^^^^
  File "C:\Users\PC\Desktop\pythonProject\Project11\.venv\Lib\site-packages\telebot\__init__.py", line 647, in get_updates
    json_updates = apihelper.get_updates(
                   ^^^^^^^^^^^^^^^^^^^^^^
  File "C:\Users\PC\Desktop\pythonProject\Project11\.venv\Lib\site-packages\telebot\apihelper.py", line 327, in get_updates
    return _make_request(token, method_url, params=payload)
           ^^^^^^^^^^^^^^^^^^^^^^^^^^^^^^^^^^^^^^^^^^^^^^^^
  File "C:\Users\PC\Desktop\pythonProject\Project11\.venv\Lib\site-packages\telebot\apihelper.py", line 161, in _make_request
    result = _get_req_session().request(
             ^^^^^^^^^^^^^^^^^^^^^^^^^^^
  File "C:\Users\PC\Desktop\pythonProject\Project11\.venv\Lib\site-packages\requests\sessions.py", line 589, in request
    resp = self.send(prep, **send_kwargs)
           ^^^^^^^^^^^^^^^^^^^^^^^^^^^^^^
  File "C:\Users\PC\Desktop\pythonProject\Project11\.venv\Lib\site-packages\requests\sessions.py", line 703, in send
    r = adapter.send(request, **kwargs)
        ^^^^^^^^^^^^^^^^^^^^^^^^^^^^^^^
  File "C:\Users\PC\Desktop\pythonProject\Project11\.venv\Lib\site-packages\requests\adapters.py", line 519, in send
    raise ConnectionError(e, request=request)
requests.exceptions.ConnectionError: HTTPSConnectionPool(host='api.telegram.org', port=443): Max retries exceeded with url: /bot6808640258:AAGUcVSRqPciK6qeM30saCt-6jquSDP4gWI/getUpdates?offset=56924450&timeout=20 (Caused by NameResolutionError("<urllib3.connection.HTTPSConnection object at 0x000001ABEB3B0C50>: Failed to resolve 'api.telegram.org' ([Errno 11001] getaddrinfo failed)"))

